Workbook

Sheet Attendance Tracker
A1: MERN STACK COURSE — 4 MONTH ATTENDANCE REGISTER
A3: Course Name | B3: MERN Stack Development | F3: Attendance Codes
A4: Duration | B4: 4 Months | F4: P | G4: Present
A5: Instructor | B5: Enter Instructor Name | F5: A | G5: Absent
A6: Student Name | B6: Enter Student Name | F6: L | G6: Leave
A7: Batch / Mode | B7: Online / Offline
A8: Course Start Date | B8: 46268
A10: Date | B10: Day | C10: Topic / Module | D10: Attendance | E10: Remarks | F10: Present | G10: Absent | H10: Leave
A11: =IF($B$8="","",$B$8+0) | B11: =IF(A11="","",TEXT(A11,"ddd")) | F11: =IF(D11="P",1,0) | G11: =IF(D11="A",1,0) | H11: =IF(D11="L",1,0)
A12: =IF($B$8="","",$B$8+1) | B12: =IF(A12="","",TEXT(A12,"ddd")) | F12: =IF(D12="P",1,0) | G12: =IF(D12="A",1,0) | H12: =IF(D12="L",1,0)
A13: =IF($B$8="","",$B$8+2) | B13: =IF(A13="","",TEXT(A13,"ddd")) | F13: =IF(D13="P",1,0) | G13: =IF(D13="A",1,0) | H13: =IF(D13="L",1,0)
A14: =IF($B$8="","",$B$8+3) | B14: =IF(A14="","",TEXT(A14,"ddd")) | F14: =IF(D14="P",1,0) | G14: =IF(D14="A",1,0) | H14: =IF(D14="L",1,0)
A15: =IF($B$8="","",$B$8+4) | B15: =IF(A15="","",TEXT(A15,"ddd")) | F15: =IF(D15="P",1,0) | G15: =IF(D15="A",1,0) | H15: =IF(D15="L",1,0)
A16: =IF($B$8="","",$B$8+5) | B16: =IF(A16="","",TEXT(A16,"ddd")) | F16: =IF(D16="P",1,0) | G16: =IF(D16="A",1,0) | H16: =IF(D16="L",1,0)
A17: =IF($B$8="","",$B$8+6) | B17: =IF(A17="","",TEXT(A17,"ddd")) | F17: =IF(D17="P",1,0) | G17: =IF(D17="A",1,0) | H17: =IF(D17="L",1,0)
A18: =IF($B$8="","",$B$8+7) | B18: =IF(A18="","",TEXT(A18,"ddd")) | F18: =IF(D18="P",1,0) | G18: =IF(D18="A",1,0) | H18: =IF(D18="L",1,0)
A19: =IF($B$8="","",$B$8+8) | B19: =IF(A19="","",TEXT(A19,"ddd")) | F19: =IF(D19="P",1,0) | G19: =IF(D19="A",1,0) | H19: =IF(D19="L",1,0)
A20: =IF($B$8="","",$B$8+9) | B20: =IF(A20="","",TEXT(A20,"ddd")) | F20: =IF(D20="P",1,0) | G20: =IF(D20="A",1,0) | H20: =IF(D20="L",1,0)
A21: =IF($B$8="","",$B$8+10) | B21: =IF(A21="","",TEXT(A21,"ddd")) | F21: =IF(D21="P",1,0) | G21: =IF(D21="A",1,0) | H21: =IF(D21="L",1,0)
A22: =IF($B$8="","",$B$8+11) | B22: =IF(A22="","",TEXT(A22,"ddd")) | F22: =IF(D22="P",1,0) | G22: =IF(D22="A",1,0) | H22: =IF(D22="L",1,0)
A23: =IF($B$8="","",$B$8+12) | B23: =IF(A23="","",TEXT(A23,"ddd")) | F23: =IF(D23="P",1,0) | G23: =IF(D23="A",1,0) | H23: =IF(D23="L",1,0)
A24: =IF($B$8="","",$B$8+13) | B24: =IF(A24="","",TEXT(A24,"ddd")) | F24: =IF(D24="P",1,0) | G24: =IF(D24="A",1,0) | H24: =IF(D24="L",1,0)
A25: =IF($B$8="","",$B$8+14) | B25: =IF(A25="","",TEXT(A25,"ddd")) | F25: =IF(D25="P",1,0) | G25: =IF(D25="A",1,0) | H25: =IF(D25="L",1,0)
A26: =IF($B$8="","",$B$8+15) | B26: =IF(A26="","",TEXT(A26,"ddd")) | F26: =IF(D26="P",1,0) | G26: =IF(D26="A",1,0) | H26: =IF(D26="L",1,0)
A27: =IF($B$8="","",$B$8+16) | B27: =IF(A27="","",TEXT(A27,"ddd")) | F27: =IF(D27="P",1,0) | G27: =IF(D27="A",1,0) | H27: =IF(D27="L",1,0)
A28: =IF($B$8="","",$B$8+17) | B28: =IF(A28="","",TEXT(A28,"ddd")) | F28: =IF(D28="P",1,0) | G28: =IF(D28="A",1,0) | H28: =IF(D28="L",1,0)
A29: =IF($B$8="","",$B$8+18) | B29: =IF(A29="","",TEXT(A29,"ddd")) | F29: =IF(D29="P",1,0) | G29: =IF(D29="A",1,0) | H29: =IF(D29="L",1,0)
A30: =IF($B$8="","",$B$8+19) | B30: =IF(A30="","",TEXT(A30,"ddd")) | F30: =IF(D30="P",1,0) | G30: =IF(D30="A",1,0) | H30: =IF(D30="L",1,0)
A31: =IF($B$8="","",$B$8+20) | B31: =IF(A31="","",TEXT(A31,"ddd")) | F31: =IF(D31="P",1,0) | G31: =IF(D31="A",1,0) | H31: =IF(D31="L",1,0)
A32: =IF($B$8="","",$B$8+21) | B32: =IF(A32="","",TEXT(A32,"ddd")) | F32: =IF(D32="P",1,0) | G32: =IF(D32="A",1,0) | H32: =IF(D32="L",1,0)
A33: =IF($B$8="","",$B$8+22) | B33: =IF(A33="","",TEXT(A33,"ddd")) | F33: =IF(D33="P",1,0) | G33: =IF(D33="A",1,0) | H33: =IF(D33="L",1,0)
A34: =IF($B$8="","",$B$8+23) | B34: =IF(A34="","",TEXT(A34,"ddd")) | F34: =IF(D34="P",1,0) | G34: =IF(D34="A",1,0) | H34: =IF(D34="L",1,0)
A35: =IF($B$8="","",$B$8+24) | B35: =IF(A35="","",TEXT(A35,"ddd")) | F35: =IF(D35="P",1,0) | G35: =IF(D35="A",1,0) | H35: =IF(D35="L",1,0)
A36: =IF($B$8="","",$B$8+25) | B36: =IF(A36="","",TEXT(A36,"ddd")) | F36: =IF(D36="P",1,0) | G36: =IF(D36="A",1,0) | H36: =IF(D36="L",1,0)
A37: =IF($B$8="","",$B$8+26) | B37: =IF(A37="","",TEXT(A37,"ddd")) | F37: =IF(D37="P",1,0) | G37: =IF(D37="A",1,0) | H37: =IF(D37="L",1,0)
A38: =IF($B$8="","",$B$8+27) | B38: =IF(A38="","",TEXT(A38,"ddd")) | F38: =IF(D38="P",1,0) | G38: =IF(D38="A",1,0) | H38: =IF(D38="L",1,0)
A39: =IF($B$8="","",$B$8+28) | B39: =IF(A39="","",TEXT(A39,"ddd")) | F39: =IF(D39="P",1,0) | G39: =IF(D39="A",1,0) | H39: =IF(D39="L",1,0)
A40: =IF($B$8="","",$B$8+29) | B40: =IF(A40="","",TEXT(A40,"ddd")) | F40: =IF(D40="P",1,0) | G40: =IF(D40="A",1,0) | H40: =IF(D40="L",1,0)
A41: =IF($B$8="","",$B$8+30) | B41: =IF(A41="","",TEXT(A41,"ddd")) | F41: =IF(D41="P",1,0) | G41: =IF(D41="A",1,0) | H41: =IF(D41="L",1,0)
A42: =IF($B$8="","",$B$8+31) | B42: =IF(A42="","",TEXT(A42,"ddd")) | F42: =IF(D42="P",1,0) | G42: =IF(D42="A",1,0) | H42: =IF(D42="L",1,0)
...

Sheet 4-Month Summary
A1: MERN STACK COURSE — ATTENDANCE SUMMARY
A3: Student Name | B3: ='Attendance Tracker'!B6
A4: Course | B4: ='Attendance Tracker'!B3
A5: Start Date | B5: ='Attendance Tracker'!B8
A8: Month | B8: Total Classes | C8: Present | D8: Absent | E8: Leave | F8: Attendance %
A9: Month 1 | B9: =COUNT('Attendance Tracker'!D11:D40) | C9: =COUNTIF('Attendance Tracker'!D11:D40,"P") | D9: =COUNTIF('Attendance Tracker'!D11:D40,"A") | E9: =COUNTIF('Attendance Tracker'!D11:D40,"L") | F9: =IF(B9=0,0,C9/B9)
A10: Month 2 | B10: =COUNT('Attendance Tracker'!D41:D70) | C10: =COUNTIF('Attendance Tracker'!D41:D70,"P") | D10: =COUNTIF('Attendance Tracker'!D41:D70,"A") | E10: =COUNTIF('Attendance Tracker'!D41:D70,"L") | F10: =IF(B10=0,0,C10/B10)
A11: Month 3 | B11: =COUNT('Attendance Tracker'!D71:D100) | C11: =COUNTIF('Attendance Tracker'!D71:D100,"P") | D11: =COUNTIF('Attendance Tracker'!D71:D100,"A") | E11: =COUNTIF('Attendance Tracker'!D71:D100,"L") | F11: =IF(B11=0,0,C11/B11)
A12: Month 4 | B12: =COUNT('Attendance Tracker'!D101:D130) | C12: =COUNTIF('Attendance Tracker'!D101:D130,"P") | D12: =COUNTIF('Attendance Tracker'!D101:D130,"A") | E12: =COUNTIF('Attendance Tracker'!D101:D130,"L") | F12: =IF(B12=0,0,C12/B12)
A13: 4-MONTH TOTAL | B13: =SUM(B9:B12) | C13: =SUM(C9:C12) | D13: =SUM(D9:D12) | E13: =SUM(E9:E12) | F13: =IF(B13=0,0,C13/B13)

Sheet Month 1
A1: MERN STACK COURSE — MONTH 1 ATTENDANCE
A3: Date | B3: Day | C3: Topic / Module | D3: Attendance | E3: Remarks | F3: Present | G3: Absent
A4: ='Attendance Tracker'!A11 | B4: ='Attendance Tracker'!B11 | C4: ='Attendance Tracker'!C11 | D4: ='Attendance Tracker'!D11 | E4: ='Attendance Tracker'!E11 | F4: ='Attendance Tracker'!F11 | G4: ='Attendance Tracker'!G11
A5: ='Attendance Tracker'!A12 | B5: ='Attendance Tracker'!B12 | C5: ='Attendance Tracker'!C12 | D5: ='Attendance Tracker'!D12 | E5: ='Attendance Tracker'!E12 | F5: ='Attendance Tracker'!F12 | G5: ='Attendance Tracker'!G12
A6: ='Attendance Tracker'!A13 | B6: ='Attendance Tracker'!B13 | C6: ='Attendance Tracker'!C13 | D6: ='Attendance Tracker'!D13 | E6: ='Attendance Tracker'!E13 | F6: ='Attendance Tracker'!F13 | G6: ='Attendance Tracker'!G13
A7: ='Attendance Tracker'!A14 | B7: ='Attendance Tracker'!B14 | C7: ='Attendance Tracker'!C14 | D7: ='Attendance Tracker'!D14 | E7: ='Attendance Tracker'!E14 | F7: ='Attendance Tracker'!F14 | G7: ='Attendance Tracker'!G14
A8: ='Attendance Tracker'!A15 | B8: ='Attendance Tracker'!B15 | C8: ='Attendance Tracker'!C15 | D8: ='Attendance Tracker'!D15 | E8: ='Attendance Tracker'!E15 | F8: ='Attendance Tracker'!F15 | G8: ='Attendance Tracker'!G15
A9: ='Attendance Tracker'!A16 | B9: ='Attendance Tracker'!B16 | C9: ='Attendance Tracker'!C16 | D9: ='Attendance Tracker'!D16 | E9: ='Attendance Tracker'!E16 | F9: ='Attendance Tracker'!F16 | G9: ='Attendance Tracker'!G16
A10: ='Attendance Tracker'!A17 | B10: ='Attendance Tracker'!B17 | C10: ='Attendance Tracker'!C17 | D10: ='Attendance Tracker'!D17 | E10: ='Attendance Tracker'!E17 | F10: ='Attendance Tracker'!F17 | G10: ='Attendance Tracker'!G17
A11: ='Attendance Tracker'!A18 | B11: ='Attendance Tracker'!B18 | C11: ='Attendance Tracker'!C18 | D11: ='Attendance Tracker'!D18 | E11: ='Attendance Tracker'!E18 | F11: ='Attendance Tracker'!F18 | G11: ='Attendance Tracker'!G18
A12: ='Attendance Tracker'!A19 | B12: ='Attendance Tracker'!B19 | C12: ='Attendance Tracker'!C19 | D12: ='Attendance Tracker'!D19 | E12: ='Attendance Tracker'!E19 | F12: ='Attendance Tracker'!F19 | G12: ='Attendance Tracker'!G19
A13: ='Attendance Tracker'!A20 | B13: ='Attendance Tracker'!B20 | C13: ='Attendance Tracker'!C20 | D13: ='Attendance Tracker'!D20 | E13: ='Attendance Tracker'!E20 | F13: ='Attendance Tracker'!F20 | G13: ='Attendance Tracker'!G20
A14: ='Attendance Tracker'!A21 | B14: ='Attendance Tracker'!B21 | C14: ='Attendance Tracker'!C21 | D14: ='Attendance Tracker'!D21 | E14: ='Attendance Tracker'!E21 | F14: ='Attendance Tracker'!F21 | G14: ='Attendance Tracker'!G21
A15: ='Attendance Tracker'!A22 | B15: ='Attendance Tracker'!B22 | C15: ='Attendance Tracker'!C22 | D15: ='Attendance Tracker'!D22 | E15: ='Attendance Tracker'!E22 | F15: ='Attendance Tracker'!F22 | G15: ='Attendance Tracker'!G22
... A33: ='Attendance Tracker'!A40 | B33: ='Attendance Tracker'!B40 | C33: ='Attendance Tracker'!C40 | D33: ='Attendance Tracker'!D40 | E33: ='Attendance Tracker'!E40 | F33: ='Attendance Tracker'!F40 | G33: ='Attendance Tracker'!G40

Sheet Month 2
A1: MERN STACK COURSE — MONTH 2 ATTENDANCE
A3: Date | B3: Day | C3: Topic / Module | D3: Attendance | E3: Remarks | F3: Present | G3: Absent
A4: ='Attendance Tracker'!A41 | B4: ='Attendance Tracker'!B41 | C4: ='Attendance Tracker'!C41 | D4: ='Attendance Tracker'!D41 | E4: ='Attendance Tracker'!E41 | F4: ='Attendance Tracker'!F41 | G4: ='Attendance Tracker'!G41
A5: ='Attendance Tracker'!A42 | B5: ='Attendance Tracker'!B42 | C5: ='Attendance Tracker'!C42 | D5: ='Attendance Tracker'!D42 | E5: ='Attendance Tracker'!E42 | F5: ='Attendance Tracker'!F42 | G5: ='Attendance Tracker'!G42
A6: ='Attendance Tracker'!A43 | B6: ='Attendance Tracker'!B43 | C6: ='Attendance Tracker'!C43 | D6: ='Attendance Tracker'!D43 | E6: ='Attendance Tracker'!E43 | F6: ='Attendance Tracker'!F43 | G6: ='Attendance Tracker'!G43
A7: ='Attendance Tracker'!A44 | B7: ='Attendance Tracker'!B44 | C7: ='Attendance Tracker'!C44 | D7: ='Attendance Tracker'!D44 | E7: ='Attendance Tracker'!E44 | F7: ='Attendance Tracker'!F44 | G7: ='Attendance Tracker'!G44
A8: ='Attendance Tracker'!A45 | B8: ='Attendance Tracker'!B45 | C8: ='Attendance Tracker'!C45 | D8: ='Attendance Tracker'!D45 | E8: ='Attendance Tracker'!E45 | F8: ='Attendance Tracker'!F45 | G8: ='Attendance Tracker'!G45
A9: ='Attendance Tracker'!A46 | B9: ='Attendance Tracker'!B46 | C9: ='Attendance Tracker'!C46 | D9: ='Attendance Tracker'!D46 | E9: ='Attendance Tracker'!E46 | F9: ='Attendance Tracker'!F46 | G9: ='Attendance Tracker'!G46
A10: ='Attendance Tracker'!A47 | B10: ='Attendance Tracker'!B47 | C10: ='Attendance Tracker'!C47 | D10: ='Attendance Tracker'!D47 | E10: ='Attendance Tracker'!E47 | F10: ='Attendance Tracker'!F47 | G10: ='Attendance Tracker'!G47
A11: ='Attendance Tracker'!A48 | B11: ='Attendance Tracker'!B48 | C11: ='Attendance Tracker'!C48 | D11: ='Attendance Tracker'!D48 | E11: ='Attendance Tracker'!E48 | F11: ='Attendance Tracker'!F48 | G11: ='Attendance Tracker'!G48
A12: ='Attendance Tracker'!A49 | B12: ='Attendance Tracker'!B49 | C12: ='Attendance Tracker'!C49 | D12: ='Attendance Tracker'!D49 | E12: ='Attendance Tracker'!E49 | F12: ='Attendance Tracker'!F49 | G12: ='Attendance Tracker'!G49
A13: ='Attendance Tracker'!A50 | B13: ='Attendance Tracker'!B50 | C13: ='Attendance Tracker'!C50 | D13: ='Attendance Tracker'!D50 | E13: ='Attendance Tracker'!E50 | F13: ='Attendance Tracker'!F50 | G13: ='Attendance Tracker'!G50
A14: ='Attendance Tracker'!A51 | B14: ='Attendance Tracker'!B51 | C14: ='Attendance Tracker'!C51 | D14: ='Attendance Tracker'!D51 | E14: ='Attendance Tracker'!E51 | F14: ='Attendance Tracker'!F51 | G14: ='Attendance Tracker'!G51
A15: ='Attendance Tracker'!A52 | B15: ='Attendance Tracker'!B52 | C15: ='Attendance Tracker'!C52 | D15: ='Attendance Tracker'!D52 | E15: ='Attendance Tracker'!E52 | F15: ='Attendance Tracker'!F52 | G15: ='Attendance Tracker'!G52
... A33: ='Attendance Tracker'!A70 | B33: ='Attendance Tracker'!B70 | C33: ='Attendance Tracker'!C70 | D33: ='Attendance Tracker'!D70 | E33: ='Attendance Tracker'!E70 | F33: ='Attendance Tracker'!F70 | G33: ='Attendance Tracker'!G70

Sheet Month 3
A1: MERN STACK COURSE — MONTH 3 ATTENDANCE
A3: Date | B3: Day | C3: Topic / Module | D3: Attendance | E3: Remarks | F3: Present | G3: Absent
A4: ='Attendance Tracker'!A71 | B4: ='Attendance Tracker'!B71 | C4: ='Attendance Tracker'!C71 | D4: ='Attendance Tracker'!D71 | E4: ='Attendance Tracker'!E71 | F4: ='Attendance Tracker'!F71 | G4: ='Attendance Tracker'!G71
A5: ='Attendance Tracker'!A72 | B5: ='Attendance Tracker'!B72 | C5: ='Attendance Tracker'!C72 | D5: ='Attendance Tracker'!D72 | E5: ='Attendance Tracker'!E72 | F5: ='Attendance Tracker'!F72 | G5: ='Attendance Tracker'!G72
A6: ='Attendance Tracker'!A73 | B6: ='Attendance Tracker'!B73 | C6: ='Attendance Tracker'!C73 | D6: ='Attendance Tracker'!D73 | E6: ='Attendance Tracker'!E73 | F6: ='Attendance Tracker'!F73 | G6: ='Attendance Tracker'!G73
A7: ='Attendance Tracker'!A74 | B7: ='Attendance Tracker'!B74 | C7: ='Attendance Tracker'!C74 | D7: ='Attendance Tracker'!D74 | E7: ='Attendance Tracker'!E74 | F7: ='Attendance Tracker'!F74 | G7: ='Attendance Tracker'!G74
A8: ='Attendance Tracker'!A75 | B8: ='Attendance Tracker'!B75 | C8: ='Attendance Tracker'!C75 | D8: ='Attendance Tracker'!D75 | E8: ='Attendance Tracker'!E75 | F8: ='Attendance Tracker'!F75 | G8: ='Attendance Tracker'!G75
A9: ='Attendance Tracker'!A76 | B9: ='Attendance Tracker'!B76 | C9: ='Attendance Tracker'!C76 | D9: ='Attendance Tracker'!D76 | E9: ='Attendance Tracker'!E76 | F9: ='Attendance Tracker'!F76 | G9: ='Attendance Tracker'!G76
A10: ='Attendance Tracker'!A77 | B10: ='Attendance Tracker'!B77 | C10: ='Attendance Tracker'!C77 | D10: ='Attendance Tracker'!D77 | E10: ='Attendance Tracker'!E77 | F10: ='Attendance Tracker'!F77 | G10: ='Attendance Tracker'!G77
A11: ='Attendance Tracker'!A78 | B11: ='Attendance Tracker'!B78 | C11: ='Attendance Tracker'!C78 | D11: ='Attendance Tracker'!D78 | E11: ='Attendance Tracker'!E78 | F11: ='Attendance Tracker'!F78 | G11: ='Attendance Tracker'!G78
A12: ='Attendance Tracker'!A79 | B12: ='Attendance Tracker'!B79 | C12: ='Attendance Tracker'!C79 | D12: ='Attendance Tracker'!D79 | E12: ='Attendance Tracker'!E79 | F12: ='Attendance Tracker'!F79 | G12: ='Attendance Tracker'!G79
A13: ='Attendance Tracker'!A80 | B13: ='Attendance Tracker'!B80 | C13: ='Attendance Tracker'!C80 | D13: ='Attendance Tracker'!D80 | E13: ='Attendance Tracker'!E80 | F13: ='Attendance Tracker'!F80 | G13: ='Attendance Tracker'!G80
A14: ='Attendance Tracker'!A81 | B14: ='Attendance Tracker'!B81 | C14: ='Attendance Tracker'!C81 | D14: ='Attendance Tracker'!D81 | E14: ='Attendance Tracker'!E81 | F14: ='Attendance Tracker'!F81 | G14: ='Attendance Tracker'!G81
A15: ='Attendance Tracker'!A82 | B15: ='Attendance Tracker'!B82 | C15: ='Attendance Tracker'!C82 | D15: ='Attendance Tracker'!D82 | E15: ='Attendance Tracker'!E82 | F15: ='Attendance Tracker'!F82 | G15: ='Attendance Tracker'!G82
... A33: ='Attendance Tracker'!A100 | B33: ='Attendance Tracker'!B100 | C33: ='Attendance Tracker'!C100 | D33: ='Attendance Tracker'!D100 | E33: ='Attendance Tracker'!E100 | F33: ='Attendance Tracker'!F100 | G33: ='Attendance Tracker'!G100

Sheet Month 4
A1: MERN STACK COURSE — MONTH 4 ATTENDANCE
A3: Date | B3: Day | C3: Topic / Module | D3: Attendance | E3: Remarks | F3: Present | G3: Absent
A4: ='Attendance Tracker'!A101 | B4: ='Attendance Tracker'!B101 | C4: ='Attendance Tracker'!C101 | D4: ='Attendance Tracker'!D101 | E4: ='Attendance Tracker'!E101 | F4: ='Attendance Tracker'!F101 | G4: ='Attendance Tracker'!G101
A5: ='Attendance Tracker'!A102 | B5: ='Attendance Tracker'!B102 | C5: ='Attendance Tracker'!C102 | D5: ='Attendance Tracker'!D102 | E5: ='Attendance Tracker'!E102 | F5: ='Attendance Tracker'!F102 | G5: ='Attendance Tracker'!G102
A6: ='Attendance Tracker'!A103 | B6: ='Attendance Tracker'!B103 | C6: ='Attendance Tracker'!C103 | D6: ='Attendance Tracker'!D103 | E6: ='Attendance Tracker'!E103 | F6: ='Attendance Tracker'!F103 | G6: ='Attendance Tracker'!G103
A7: ='Attendance Tracker'!A104 | B7: ='Attendance Tracker'!B104 | C7: ='Attendance Tracker'!C104 | D7: ='Attendance Tracker'!D104 | E7: ='Attendance Tracker'!E104 | F7: ='Attendance Tracker'!F104 | G7: ='Attendance Tracker'!G104
A8: ='Attendance Tracker'!A105 | B8: ='Attendance Tracker'!B105 | C8: ='Attendance Tracker'!C105 | D8: ='Attendance Tracker'!D105 | E8: ='Attendance Tracker'!E105 | F8: ='Attendance Tracker'!F105 | G8: ='Attendance Tracker'!G105
A9: ='Attendance Tracker'!A106 | B9: ='Attendance Tracker'!B106 | C9: ='Attendance Tracker'!C106 | D9: ='Attendance Tracker'!D106 | E9: ='Attendance Tracker'!E106 | F9: ='Attendance Tracker'!F106 | G9: ='Attendance Tracker'!G106
A10: ='Attendance Tracker'!A107 | B10: ='Attendance Tracker'!B107 | C10: ='Attendance Tracker'!C107 | D10: ='Attendance Tracker'!D107 | E10: ='Attendance Tracker'!E107 | F10: ='Attendance Tracker'!F107 | G10: ='Attendance Tracker'!G107
A11: ='Attendance Tracker'!A108 | B11: ='Attendance Tracker'!B108 | C11: ='Attendance Tracker'!C108 | D11: ='Attendance Tracker'!D108 | E11: ='Attendance Tracker'!E108 | F11: ='Attendance Tracker'!F108 | G11: ='Attendance Tracker'!G108
A12: ='Attendance Tracker'!A109 | B12: ='Attendance Tracker'!B109 | C12: ='Attendance Tracker'!C109 | D12: ='Attendance Tracker'!D109 | E12: ='Attendance Tracker'!E109 | F12: ='Attendance Tracker'!F109 | G12: ='Attendance Tracker'!G109
A13: ='Attendance Tracker'!A110 | B13: ='Attendance Tracker'!B110 | C13: ='Attendance Tracker'!C110 | D13: ='Attendance Tracker'!D110 | E13: ='Attendance Tracker'!E110 | F13: ='Attendance Tracker'!F110 | G13: ='Attendance Tracker'!G110
A14: ='Attendance Tracker'!A111 | B14: ='Attendance Tracker'!B111 | C14: ='Attendance Tracker'!C111 | D14: ='Attendance Tracker'!D111 | E14: ='Attendance Tracker'!E111 | F14: ='Attendance Tracker'!F111 | G14: ='Attendance Tracker'!G111
A15: ='Attendance Tracker'!A112 | B15: ='Attendance Tracker'!B112 | C15: ='Attendance Tracker'!C112 | D15: ='Attendance Tracker'!D112 | E15: ='Attendance Tracker'!E112 | F15: ='Attendance Tracker'!F112 | G15: ='Attendance Tracker'!G112
... A33: ='Attendance Tracker'!A130 | B33: ='Attendance Tracker'!B130 | C33: ='Attendance Tracker'!C130 | D33: ='Attendance Tracker'!D130 | E33: ='Attendance Tracker'!E130 | F33: ='Attendance Tracker'!F130 | G33: ='Attendance Tracker'!G130
